Workbook

Sheet Healthcare_Sales_Dataset
A1: OrderID | B1: Product | C1: Region | D1: Salesperson | E1: UnitsSold | F1: UnitPrice | G1: Discount (%) | H1: ReturnStatus | I1: OrderDate | J1: TotalSales | K1: Deducations | L1: ExpectedSales | M1: Day | N1: Month | O1: Year | P1: PriceTag | Q1: SalesTag | R1: DiscountTag | S1: ReturnTag | T1: RegionCode
A2: ORD0001 | B2: Syringe Pack | C2: South | D2: Henry Davis | E2: 6 | F2: 500 | G2: 10 | H2: No | I2: 44986 | J2: =E2*F2*(1-G2/100) -> 2700 | K2: =ROUND(J2*15%,2) -> 405 | L2: =E2*F2 -> 3000 | M2: =DAY(I2) -> 1 | N2: =MONTH(I2) -> 3 | O2: =YEAR(I2) -> 2023 | P2: =IF(F2<500,"Low Price","High Price") -> High Price | Q2: =IF(J2>=AVERAGE(J:J),"Good","Bad") -> Bad | R2: =IF(G2>10,"High Discount",IF(G2=0,"No Discount","Low Discont")) -> Low Discont | S2: =IF(AND(H2="Yes",G2>10),"High Priority Review",IF(H2="Yes","Low Priority Review","No Review Needed")) -> No Review Needed | T2: =LEFT(C2,2) -> So
A3: ORD0002 | B3: Syringe Pack | C3: North | D3: Catherine Lee | E3: 3 | F3: 500 | G3: 10 | H3: No | I3: 44986 | J3: =E3*F3*(1-G3/100) -> 1350 | K3: =ROUND(J3*15%,2) -> 202.5 | L3: =E3*F3 -> 1500 | M3: =DAY(I3) -> 1 | N3: =MONTH(I3) -> 3 | O3: =YEAR(I3) -> 2023 | P3: =IF(F3<500,"Low Price","High Price") -> High Price | Q3: =IF(J3>=AVERAGE(J:J),"Good","Bad") -> Bad | R3: =IF(G3>10,"High Discount",IF(G3=0,"No Discount","Low Discont")) -> Low Discont | S3: =IF(AND(H3="Yes",G3>10),"High Priority Review",IF(H3="Yes","Low Priority Review","No Review Needed")) -> No Review Needed | T3: =LEFT(C3,2) -> No
A4: ORD0003 | B4: X-Ray Machine | C4: West | D4: David Miller | E4: 9 | F4: 5000 | G4: 10 | H4: Yes | I4: 45047 | J4: =E4*F4*(1-G4/100) -> 40500 | K4: =ROUND(J4*15%,2) -> 6075 | L4: =E4*F4 -> 45000 | M4: =DAY(I4) -> 1 | N4: =MONTH(I4) -> 5 | O4: =YEAR(I4) -> 2023 | P4: =IF(F4<500,"Low Price","High Price") -> High Price | Q4: =IF(J4>=AVERAGE(J:J),"Good","Bad") -> Good | R4: =IF(G4>10,"High Discount",IF(G4=0,"No Discount","Low Discont")) -> Low Discont | S4: =IF(AND(H4="Yes",G4>10),"High Priority Review",IF(H4="Yes","Low Priority Review","No Review Needed")) -> Low Priority Review | T4: =LEFT(C4,2) -> We
A5: ORD0004 | B5: Ultrasound Device | C5: West | D5: David Miller | E5: 2 | F5: 2000 | G5: 5 | H5: Yes | I5: 45078 | J5: =E5*F5*(1-G5/100) -> 3800 | K5: =ROUND(J5*15%,2) -> 570 | L5: =E5*F5 -> 4000 | M5: =DAY(I5) -> 1 | N5: =MONTH(I5) -> 6 | O5: =YEAR(I5) -> 2023 | P5: =IF(F5<500,"Low Price","High Price") -> High Price | Q5: =IF(J5>=AVERAGE(J:J),"Good","Bad") -> Bad | R5: =IF(G5>10,"High Discount",IF(G5=0,"No Discount","Low Discont")) -> Low Discont | S5: =IF(AND(H5="Yes",G5>10),"High Priority Review",IF(H5="Yes","Low Priority Review","No Review Needed")) -> Low Priority Review | T5: =LEFT(C5,2) -> We
A6: ORD0005 | B6: Stethoscope | C6: East | E6: 3 | F6: 750 | G6: 5 | H6: Yes | I6: 45139 | J6: =E6*F6*(1-G6/100) -> 2137.5 | K6: =ROUND(J6*15%,2) -> 320.63 | L6: =E6*F6 -> 2250 | M6: =DAY(I6) -> 1 | N6: =MONTH(I6) -> 8 | O6: =YEAR(I6) -> 2023 | P6: =IF(F6<500,"Low Price","High Price") -> High Price | Q6: =IF(J6>=AVERAGE(J:J),"Good","Bad") -> Bad | R6: =IF(G6>10,"High Discount",IF(G6=0,"No Discount","Low Discont")) -> Low Discont | S6: =IF(AND(H6="Yes",G6>10),"High Priority Review",IF(H6="Yes","Low Priority Review","No Review Needed")) -> Low Priority Review | T6: =LEFT(C6,2) -> Ea
A7: ORD0006 | B7: Thermometer | C7: North | D7: Catherine Lee | E7: 14 | F7: 250 | G7: 10 | H7: No | I7: 45139 | J7: =E7*F7*(1-G7/100) -> 3150 | K7: =ROUND(J7*15%,2) -> 472.5 | L7: =E7*F7 -> 3500 | M7: =DAY(I7) -> 1 | N7: =MONTH(I7) -> 8 | O7: =YEAR(I7) -> 2023 | P7: =IF(F7<500,"Low Price","High Price") -> Low Price | Q7: =IF(J7>=AVERAGE(J:J),"Good","Bad") -> Bad | R7: =IF(G7>10,"High Discount",IF(G7=0,"No Discount","Low Discont")) -> Low Discont | S7: =IF(AND(H7="Yes",G7>10),"High Priority Review",IF(H7="Yes","Low Priority Review","No Review Needed")) -> No Review Needed | T7: =LEFT(C7,2) -> No
A8: ORD0007 | B8: Thermometer | C8: East | D8: Grace Kim | E8: 25 | F8: 250 | G8: 15 | H8: No | I8: 45139 | J8: =E8*F8*(1-G8/100) -> 5312.5 | K8: =ROUND(J8*15%,2) -> 796.88 | L8: =E8*F8 -> 6250 | M8: =DAY(I8) -> 1 | N8: =MONTH(I8) -> 8 | O8: =YEAR(I8) -> 2023 | P8: =IF(F8<500,"Low Price","High Price") -> Low Price | Q8: =IF(J8>=AVERAGE(J:J),"Good","Bad") -> Bad | R8: =IF(G8>10,"High Discount",IF(G8=0,"No Discount","Low Discont")) -> High Discount | S8: =IF(AND(H8="Yes",G8>10),"High Priority Review",IF(H8="Yes","Low Priority Review","No Review Needed")) -> No Review Needed | T8: =LEFT(C8,2) -> Ea
A9: ORD0008 | B9: Blood Test Kit | C9: North | D9: Eva Brown | E9: 49 | F9: 1750 | G9: 15 | H9: Yes | I9: 45200 | J9: =E9*F9*(1-G9/100) -> 72887.5 | K9: =ROUND(J9*15%,2) -> 10933.13 | L9: =E9*F9 -> 85750 | M9: =DAY(I9) -> 1 | N9: =MONTH(I9) -> 10 | O9: =YEAR(I9) -> 2023 | P9: =IF(F9<500,"Low Price","High Price") -> High Price | Q9: =IF(J9>=AVERAGE(J:J),"Good","Bad") -> Good | R9: =IF(G9>10,"High Discount",IF(G9=0,"No Discount","Low Discont")) -> High Discount | S9: =IF(AND(H9="Yes",G9>10),"High Priority Review",IF(H9="Yes","Low Priority Review","No Review Needed")) -> High Priority Review | T9: =LEFT(C9,2) -> No
A10: ORD0009 | B10: Stethoscope | C10: North | D10: Catherine Lee | E10: 10 | F10: 750 | G10: 5 | H10: No | I10: 45231 | J10: =E10*F10*(1-G10/100) -> 7125 | K10: =ROUND(J10*15%,2) -> 1068.75 | L10: =E10*F10 -> 7500 | M10: =DAY(I10) -> 1 | N10: =MONTH(I10) -> 11 | O10: =YEAR(I10) -> 2023 | P10: =IF(F10<500,"Low Price","High Price") -> High Price | Q10: =IF(J10>=AVERAGE(J:J),"Good","Bad") -> Bad | R10: =IF(G10>10,"High Discount",IF(G10=0,"No Discount","Low Discont")) -> Low Discont | S10: =IF(AND(H10="Yes",G10>10),"High Priority Review",IF(H10="Yes","Low Priority Review","No Review Needed")) -> No Review Needed | T10: =LEFT(C10,2) -> No
A11: ORD0010 | B11: Stethoscope | C11: East | D11: Alice Johnson | E11: 14 | F11: 750 | G11: 15 | H11: Yes | I11: 44959 | J11: =E11*F11*(1-G11/100) -> 8925 | K11: =ROUND(J11*15%,2) -> 1338.75 | L11: =E11*F11 -> 10500 | M11: =DAY(I11) -> 2 | N11: =MONTH(I11) -> 2 | O11: =YEAR(I11) -> 2023 | P11: =IF(F11<500,"Low Price","High Price") -> High Price | Q11: =IF(J11>=AVERAGE(J:J),"Good","Bad") -> Bad | R11: =IF(G11>10,"High Discount",IF(G11=0,"No Discount","Low Discont")) -> High Discount | S11: =IF(AND(H11="Yes",G11>10),"High Priority Review",IF(H11="Yes","Low Priority Review","No Review Needed")) -> High Priority Review | T11: =LEFT(C11,2) -> Ea
A12: ORD0011 | B12: X-Ray Machine | C12: West | D12: David Miller | E12: 6 | F12: 5000 | G12: 20 | H12: No | I12: 44959 | J12: =E12*F12*(1-G12/100) -> 24000 | K12: =ROUND(J12*15%,2) -> 3600 | L12: =E12*F12 -> 30000 | M12: =DAY(I12) -> 2 | N12: =MONTH(I12) -> 2 | O12: =YEAR(I12) -> 2023 | P12: =IF(F12<500,"Low Price","High Price") -> High Price | Q12: =IF(J12>=AVERAGE(J:J),"Good","Bad") -> Good | R12: =IF(G12>10,"High Discount",IF(G12=0,"No Discount","Low Discont")) -> High Discount | S12: =IF(AND(H12="Yes",G12>10),"High Priority Review",IF(H12="Yes","Low Priority Review","No Review Needed")) -> No Review Needed | T12: =LEFT(C12,2) -> We
A13: ORD0012 | B13: Thermometer | C13: East | D13: Alice Johnson | E13: 21 | F13: 250 | G13: 5 | H13: No | I13: 45109 | J13: =E13*F13*(1-G13/100) -> 4987.5 | K13: =ROUND(J13*15%,2) -> 748.13 | L13: =E13*F13 -> 5250 | M13: =DAY(I13) -> 2 | N13: =MONTH(I13) -> 7 | O13: =YEAR(I13) -> 2023 | P13: =IF(F13<500,"Low Price","High Price") -> Low Price | Q13: =IF(J13>=AVERAGE(J:J),"Good","Bad") -> Bad | R13: =IF(G13>10,"High Discount",IF(G13=0,"No Discount","Low Discont")) -> Low Discont | S13: =IF(AND(H13="Yes",G13>10),"High Priority Review",IF(H13="Yes","Low Priority Review","No Review Needed")) -> No Review Needed | T13: =LEFT(C13,2) -> Ea
A14: ORD0013 | B14: Syringe Pack | C14: East | D14: Grace Kim | E14: 32 | F14: 500 | G14: 5 | H14: Yes | I14: 45262 | J14: =E14*F14*(1-G14/100) -> 15200 | K14: =ROUND(J14*15%,2) -> 2280 | L14: =E14*F14 -> 16000 | M14: =DAY(I14) -> 2 | N14: =MONTH(I14) -> 12 | O14: =YEAR(I14) -> 2023 | P14: =IF(F14<500,"Low Price","High Price") -> High Price | Q14: =IF(J14>=AVERAGE(J:J),"Good","Bad") -> Bad | R14: =IF(G14>10,"High Discount",IF(G14=0,"No Discount","Low Discont")) -> Low Discont | S14: =IF(AND(H14="Yes",G14>10),"High Priority Review",IF(H14="Yes","Low Priority Review","No Review Needed")) -> Low Priority Review | T14: =LEFT(C14,2) -> Ea
A15: ORD0014 | B15: X-Ray Machine | C15: North | D15: Eva Brown | E15: 7 | F15: 5000 | G15: 20 | H15: Yes | I15: 45262 | J15: =E15*F15*(1-G15/100) -> 28000 | K15: =ROUND(J15*15%,2) -> 4200 | L15: =E15*F15 -> 35000 | M15: =DAY(I15) -> 2 | N15: =MONTH(I15) -> 12 | O15: =YEAR(I15) -> 2023 | P15: =IF(F15<500,"Low Price","High Price") -> High Price | Q15: =IF(J15>=AVERAGE(J:J),"Good","Bad") -> Good | R15: =IF(G15>10,"High Discount",IF(G15=0,"No Discount","Low Discont")) -> High Discount | S15: =IF(AND(H15="Yes",G15>10),"High Priority Review",IF(H15="Yes","Low Priority Review","No Review Needed")) -> High Priority Review | T15: =LEFT(C15,2) -> No
A16: ORD0015 | B16: Ultrasound Device | C16: South | D16: Henry Davis | E16: 5 | F16: 2000 | G16: 10 | H16: Yes | I16: 44988 | J16: =E16*F16*(1-G16/100) -> 9000 | K16: =ROUND(J16*15%,2) -> 1350 | L16: =E16*F16 -> 10000 | M16: =DAY(I16) -> 3 | N16: =MONTH(I16) -> 3 | O16: =YEAR(I16) -> 2023 | P16: =IF(F16<500,"Low Price","High Price") -> High Price | Q16: =IF(J16>=AVERAGE(J:J),"Good","Bad") -> Bad | R16: =IF(G16>10,"High Discount",IF(G16=0,"No Discount","Low Discont")) -> Low Discont | S16: =IF(AND(H16="Yes",G16>10),"High Priority Review",IF(H16="Yes","Low Priority Review","No Review Needed")) -> Low Priority Review | T16: =LEFT(C16,2) -> So
A17: ORD0016 | B17: Insulin Pump | C17: North | D17: Catherine Lee | E17: 49 | F17: 1000 | G17: 10 | H17: No | I17: 44988 | J17: =E17*F17*(1-G17/100) -> 44100 | K17: =ROUND(J17*15%,2) -> 6615 | L17: =E17*F17 -> 49000 | M17: =DAY(I17) -> 3 | N17: =MONTH(I17) -> 3 | O17: =YEAR(I17) -> 2023 | P17: =IF(F17<500,"Low Price","High Price") -> High Price | Q17: =IF(J17>=AVERAGE(J:J),"Good","Bad") -> Good | R17: =IF(G17>10,"High Discount",IF(G17=0,"No Discount","Low Discont")) -> Low Discont | S17: =IF(AND(H17="Yes",G17>10),"High Priority Review",IF(H17="Yes","Low Priority Review","No Review Needed")) -> No Review Needed | T17: =LEFT(C17,2) -> No
A18: ORD0017 | B18: Insulin Pump | C18: North | D18: Catherine Lee | E18: 31 | F18: 1000 | G18: 15 | H18: No | I18: 45019 | J18: =E18*F18*(1-G18/100) -> 26350 | K18: =ROUND(J18*15%,2) -> 3952.5 | L18: =E18*F18 -> 31000 | M18: =DAY(I18) -> 3 | N18: =MONTH(I18) -> 4 | O18: =YEAR(I18) -> 2023 | P18: =IF(F18<500,"Low Price","High Price") -> High Price | Q18: =IF(J18>=AVERAGE(J:J),"Good","Bad") -> Good | R18: =IF(G18>10,"High Discount",IF(G18=0,"No Discount","Low Discont")) -> High Discount | S18: =IF(AND(H18="Yes",G18>10),"High Priority Review",IF(H18="Yes","Low Priority Review","No Review Needed")) -> No Review Needed | T18: =LEFT(C18,2) -> No
... A20: ORD0019 | B20: Blood Test Kit | C20: North | D20: Eva Brown | E20: 30 | F20: 1750 | G20: 0 | H20: Yes | I20: 45172 | J20: =E20*F20*(1-G20/100) -> 52500 | K20: =ROUND(J20*15%,2) -> 7875 | L20: =E20*F20 -> 52500 | M20: =DAY(I20) -> 3 | N20: =MONTH(I20) -> 9 | O20: =YEAR(I20) -> 2023 | P20: =IF(F20<500,"Low Price","High Price") -> High Price | Q20: =IF(J20>=AVERAGE(J:J),"Good","Bad") -> Good | R20: =IF(G20>10,"High Discount",IF(G20=0,"No Discount","Low Discont")) -> No Discount | S20: =IF(AND(H20="Yes",G20>10),"High Priority Review",IF(H20="Yes","Low Priority Review","No Review Needed")) -> Low Priority Review | T20: =LEFT(C20,2) -> No
A21: ORD0020 | B21: Thermometer | C21: East | D21: Grace Kim | E21: 7 | F21: 250 | H21: No | I21: 44961 | J21: =E21*F21*(1-G21/100) -> 1750 | K21: =ROUND(J21*15%,2) -> 262.5 | L21: =E21*F21 -> 1750 | M21: =DAY(I21) -> 4 | N21: =MONTH(I21) -> 2 | O21: =YEAR(I21) -> 2023 | P21: =IF(F21<500,"Low Price","High Price") -> Low Price | Q21: =IF(J21>=AVERAGE(J:J),"Good","Bad") -> Bad | R21: =IF(G21>10,"High Discount",IF(G21=0,"No Discount","Low Discont")) -> No Discount | S21: =IF(AND(H21="Yes",G21>10),"High Priority Review",IF(H21="Yes","Low Priority Review","No Review Needed")) -> No Review Needed | T21: =LEFT(C21,2) -> Ea
A22: ORD0021 | B22: Blood Test Kit | C22: East | D22: Grace Kim | E22: 8 | F22: 1750 | G22: 10 | H22: Yes | I22: 45081 | J22: =E22*F22*(1-G22/100) -> 12600 | K22: =ROUND(J22*15%,2) -> 1890 | L22: =E22*F22 -> 14000 | M22: =DAY(I22) -> 4 | N22: =MONTH(I22) -> 6 | O22: =YEAR(I22) -> 2023 | P22: =IF(F22<500,"Low Price","High Price") -> High Price | Q22: =IF(J22>=AVERAGE(J:J),"Good","Bad") -> Bad | R22: =IF(G22>10,"High Discount",IF(G22=0,"No Discount","Low Discont")) -> Low Discont | S22: =IF(AND(H22="Yes",G22>10),"High Priority Review",IF(H22="Yes","Low Priority Review","No Review Needed")) -> Low Priority Review | T22: =LEFT(C22,2) -> Ea
A23: ORD0022 | B23: Blood Test Kit | C23: West | D23: David Miller | E23: 9 | F23: 1750 | G23: 15 | H23: Yes | I23: 45111 | J23: =E23*F23*(1-G23/100) -> 13387.5 | K23: =ROUND(J23*15%,2) -> 2008.13 | L23: =E23*F23 -> 15750 | M23: =DAY(I23) -> 4 | N23: =MONTH(I23) -> 7 | O23: =YEAR(I23) -> 2023 | P23: =IF(F23<500,"Low Price","High Price") -> High Price | Q23: =IF(J23>=AVERAGE(J:J),"Good","Bad") -> Bad | R23: =IF(G23>10,"High Discount",IF(G23=0,"No Discount","Low Discont")) -> High Discount | S23: =IF(AND(H23="Yes",G23>10),"High Priority Review",IF(H23="Yes","Low Priority Review","No Review Needed")) -> High Priority Review | T23: =LEFT(C23,2) -> We
A24: ORD0023 | B24: Insulin Pump | C24: North | D24: Catherine Lee | E24: 38 | F24: 1000 | G24: 5 | H24: Yes | I24: 45264 | J24: =E24*F24*(1-G24/100) -> 36100 | K24: =ROUND(J24*15%,2) -> 5415 | L24: =E24*F24 -> 38000 | M24: =DAY(I24) -> 4 | N24: =MONTH(I24) -> 12 | O24: =YEAR(I24) -> 2023 | P24: =IF(F24<500,"Low Price","High Price") -> High Price | Q24: =IF(J24>=AVERAGE(J:J),"Good","Bad") -> Good | R24: =IF(G24>10,"High Discount",IF(G24=0,"No Discount","Low Discont")) -> Low Discont | S24: =IF(AND(H24="Yes",G24>10),"High Priority Review",IF(H24="Yes","Low Priority Review","No Review Needed")) -> Low Priority Review | T24: =LEFT(C24,2) -> No
A25: ORD0024 | B25: Ultrasound Device | C25: North | D25: Eva Brown | E25: 3 | F25: 2000 | G25: 5 | H25: Yes | I25: 45112 | J25: =E25*F25*(1-G25/100) -> 5700 | K25: =ROUND(J25*15%,2) -> 855 | L25: =E25*F25 -> 6000 | M25: =DAY(I25) -> 5 | N25: =MONTH(I25) -> 7 | O25: =YEAR(I25) -> 2023 | P25: =IF(F25<500,"Low Price","High Price") -> High Price | Q25: =IF(J25>=AVERAGE(J:J),"Good","Bad") -> Bad | R25: =IF(G25>10,"High Discount",IF(G25=0,"No Discount","Low Discont")) -> Low Discont | S25: =IF(AND(H25="Yes",G25>10),"High Priority Review",IF(H25="Yes","Low Priority Review","No Review Needed")) -> Low Priority Review | T25: =LEFT(C25,2) -> No
A26: ORD0025 | B26: Stethoscope | C26: East | D26: Alice Johnson | E26: 6 | F26: 750 | G26: 10 | H26: No | I26: 45265 | J26: =E26*F26*(1-G26/100) -> 4050 | K26: =ROUND(J26*15%,2) -> 607.5 | L26: =E26*F26 -> 4500 | M26: =DAY(I26) -> 5 | N26: =MONTH(I26) -> 12 | O26: =YEAR(I26) -> 2023 | P26: =IF(F26<500,"Low Price","High Price") -> High Price | Q26: =IF(J26>=AVERAGE(J:J),"Good","Bad") -> Bad | R26: =IF(G26>10,"High Discount",IF(G26=0,"No Discount","Low Discont")) -> Low Discont | S26: =IF(AND(H26="Yes",G26>10),"High Priority Review",IF(H26="Yes","Low Priority Review","No Review Needed")) -> No Review Needed | T26: =LEFT(C26,2) -> Ea
A27: ORD0026 | B27: Thermometer | C27: East | D27: Alice Johnson | E27: 14 | F27: 250 | G27: 10 | H27: No | I27: 44963 | J27: =E27*F27*(1-G27/100) -> 3150 | K27: =ROUND(J27*15%,2) -> 472.5 | L27: =E27*F27 -> 3500 | M27: =DAY(I27) -> 6 | N27: =MONTH(I27) -> 2 | O27: =YEAR(I27) -> 2023 | P27: =IF(F27<500,"Low Price","High Price") -> Low Price | Q27: =IF(J27>=AVERAGE(J:J),"Good","Bad") -> Bad | R27: =IF(G27>10,"High Discount",IF(G27=0,"No Discount","Low Discont")) -> Low Discont | S27: =IF(AND(H27="Yes",G27>10),"High Priority Review",IF(H27="Yes","Low Priority Review","No Review Needed")) -> No Review Needed | T27: =LEFT(C27,2) -> Ea
A28: ORD0027 | B28: X-Ray Machine | C28: East | D28: Alice Johnson | E28: 9 | F28: 5000 | G28: 10 | H28: Yes | I28: 44991 | J28: =E28*F28*(1-G28/100) -> 40500 | K28: =ROUND(J28*15%,2) -> 6075 | L28: =E28*F28 -> 45000 | M28: =DAY(I28) -> 6 | N28: =MONTH(I28) -> 3 | O28: =YEAR(I28) -> 2023 | P28: =IF(F28<500,"Low Price","High Price") -> High Price | Q28: =IF(J28>=AVERAGE(J:J),"Good","Bad") -> Good | R28: =IF(G28>10,"High Discount",IF(G28=0,"No Discount","Low Discont")) -> Low Discont | S28: =IF(AND(H28="Yes",G28>10),"High Priority Review",IF(H28="Yes","Low Priority Review","No Review Needed")) -> Low Priority Review | T28: =LEFT(C28,2) -> Ea
A29: ORD0028 | B29: Stethoscope | C29: North | D29: Catherine Lee | E29: 3 | F29: 750 | G29: 15 | H29: Yes | I29: 44991 | J29: =E29*F29*(1-G29/100) -> 1912.5 | K29: =ROUND(J29*15%,2) -> 286.88 | L29: =E29*F29 -> 2250 | M29: =DAY(I29) -> 6 | N29: =MONTH(I29) -> 3 | O29: =YEAR(I29) -> 2023 | P29: =IF(F29<500,"Low Price","High Price") -> High Price | Q29: =IF(J29>=AVERAGE(J:J),"Good","Bad") -> Bad | R29: =IF(G29>10,"High Discount",IF(G29=0,"No Discount","Low Discont")) -> High Discount | S29: =IF(AND(H29="Yes",G29>10),"High Priority Review",IF(H29="Yes","Low Priority Review","No Review Needed")) -> High Priority Review | T29: =LEFT(C29,2) -> No
A30: ORD0029 | B30: Insulin Pump | C30: North | D30: Eva Brown | E30: 13 | F30: 1000 | G30: 20 | H30: No | I30: 44991 | J30: =E30*F30*(1-G30/100) -> 10400 | K30: =ROUND(J30*15%,2) -> 1560 | L30: =E30*F30 -> 13000 | M30: =DAY(I30) -> 6 | N30: =MONTH(I30) -> 3 | O30: =YEAR(I30) -> 2023 | P30: =IF(F30<500,"Low Price","High Price") -> High Price | Q30: =IF(J30>=AVERAGE(J:J),"Good","Bad") -> Bad | R30: =IF(G30>10,"High Discount",IF(G30=0,"No Discount","Low Discont")) -> High Discount | S30: =IF(AND(H30="Yes",G30>10),"High Priority Review",IF(H30="Yes","Low Priority Review","No Review Needed")) -> No Review Needed | T30: =LEFT(C30,2) -> No
A31: ORD0030 | B31: Insulin Pump | C31: East | D31: Alice Johnson | E31: 40 | F31: 1000 | G31: 5 | H31: No | I31: 45022 | J31: =E31*F31*(1-G31/100) -> 38000 | K31: =ROUND(J31*15%,2) -> 5700 | L31: =E31*F31 -> 40000 | M31: =DAY(I31) -> 6 | N31: =MONTH(I31) -> 4 | O31: =YEAR(I31) -> 2023 | P31: =IF(F31<500,"Low Price","High Price") -> High Price | Q31: =IF(J31>=AVERAGE(J:J),"Good","Bad") -> Good | R31: =IF(G31>10,"High Discount",IF(G31=0,"No Discount","Low Discont")) -> Low Discont | S31: =IF(AND(H31="Yes",G31>10),"High Priority Review",IF(H31="Yes","Low Priority Review","No Review Needed")) -> No Review Needed | T31: =LEFT(C31,2) -> Ea
A32: ORD0031 | B32: Ultrasound Device | C32: North | D32: Eva Brown | E32: 5 | F32: 2000 | G32: 15 | H32: Yes | I32: 45052 | J32: =E32*F32*(1-G32/100) -> 8500 | K32: =ROUND(J32*15%,2) -> 1275 | L32: =E32*F32 -> 10000 | M32: =DAY(I32) -> 6 | N32: =MONTH(I32) -> 5 | O32: =YEAR(I32) -> 2023 | P32: =IF(F32<500,"Low Price","High Price") -> High Price | Q32: =IF(J32>=AVERAGE(J:J),"Good","Bad") -> Bad | R32: =IF(G32>10,"High Discount",IF(G32=0,"No Discount","Low Discont")) -> High Discount | S32: =IF(AND(H32="Yes",G32>10),"High Priority Review",IF(H32="Yes","Low Priority Review","No Review Needed")) -> High Priority Review | T32: =LEFT(C32,2) -> No
A33: ORD0032 | B33: Blood Test Kit | C33: South | D33: Henry Davis | E33: 29 | F33: 1750 | G33: 20 | H33: No | I33: 45083 | J33: =E33*F33*(1-G33/100) -> 40600 | K33: =ROUND(J33*15%,2) -> 6090 | L33: =E33*F33 -> 50750 | M33: =DAY(I33) -> 6 | N33: =MONTH(I33) -> 6 | O33: =YEAR(I33) -> 2023 | P33: =IF(F33<500,"Low Price","High Price") -> High Price | Q33: =IF(J33>=AVERAGE(J:J),"Good","Bad") -> Good | R33: =IF(G33>10,"High Discount",IF(G33=0,"No Discount","Low Discont")) -> High Discount | S33: =IF(AND(H33="Yes",G33>10),"High Priority Review",IF(H33="Yes","Low Priority Review","No Review Needed")) -> No Review Needed | T33: =LEFT(C33,2) -> So
... A54: ORD0053 | B54: Ultrasound Device | C54: North | D54: Eva Brown | E54: 1 | F54: 2000 | G54: 15 | H54: Yes | I54: 45238 | J54: =E54*F54*(1-G54/100) -> 1700 | K54: =ROUND(J54*15%,2) -> 255 | L54: =E54*F54 -> 2000 | M54: =DAY(I54) -> 8 | N54: =MONTH(I54) -> 11 | O54: =YEAR(I54) -> 2023 | P54: =IF(F54<500,"Low Price","High Price") -> High Price | Q54: =IF(J54>=AVERAGE(J:J),"Good","Bad") -> Bad | R54: =IF(G54>10,"High Discount",IF(G54=0,"No Discount","Low Discont")) -> High Discount | S54: =IF(AND(H54="Yes",G54>10),"High Priority Review",IF(H54="Yes","Low Priority Review","No Review Needed")) -> High Priority Review | T54: =LEFT(C54,2) -> No
A55: ORD0054 | B55: X-Ray Machine | C55: North | D55: Catherine Lee | E55: 4 | F55: 5000 | H55: No | I55: 45268 | J55: =E55*F55*(1-G55/100) -> 20000 | K55: =ROUND(J55*15%,2) -> 3000 | L55: =E55*F55 -> 20000 | M55: =DAY(I55) -> 8 | N55: =MONTH(I55) -> 12 | O55: =YEAR(I55) -> 2023 | P55: =IF(F55<500,"Low Price","High Price") -> High Price | Q55: =IF(J55>=AVERAGE(J:J),"Good","Bad") -> Good | R55: =IF(G55>10,"High Discount",IF(G55=0,"No Discount","Low Discont")) -> No Discount | S55: =IF(AND(H55="Yes",G55>10),"High Priority Review",IF(H55="Yes","Low Priority Review","No Review Needed")) -> No Review Needed | T55: =LEFT(C55,2) -> No
A56: ORD0055 | B56: PPE Kit | C56: East | D56: Alice Johnson | E56: 16 | F56: 3000 | G56: 5 | H56: No | I56: 44935 | J56: =E56*F56*(1-G56/100) -> 45600 | K56: =ROUND(J56*15%,2) -> 6840 | L56: =E56*F56 -> 48000 | M56: =DAY(I56) -> 9 | N56: =MONTH(I56) -> 1 | O56: =YEAR(I56) -> 2023 | P56: =IF(F56<500,"Low Price","High Price") -> High Price | Q56: =IF(J56>=AVERAGE(J:J),"Good","Bad") -> Good | R56: =IF(G56>10,"High Discount",IF(G56=0,"No Discount","Low Discont")) -> Low Discont | S56: =IF(AND(H56="Yes",G56>10),"High Priority Review",IF(H56="Yes","Low Priority Review","No Review Needed")) -> No Review Needed | T56: =LEFT(C56,2) -> Ea
A57: ORD0056 | B57: Blood Test Kit | C57: South | D57: Henry Davis | E57: 41 | F57: 1750 | G57: 10 | H57: No | I57: 44966 | J57: =E57*F57*(1-G57/100) -> 64575 | K57: =ROUND(J57*15%,2) -> 9686.25 | L57: =E57*F57 -> 71750 | M57: =DAY(I57) -> 9 | N57: =MONTH(I57) -> 2 | O57: =YEAR(I57) -> 2023 | P57: =IF(F57<500,"Low Price","High Price") -> High Price | Q57: =IF(J57>=AVERAGE(J:J),"Good","Bad") -> Good | R57: =IF(G57>10,"High Discount",IF(G57=0,"No Discount","Low Discont")) -> Low Discont | S57: =IF(AND(H57="Yes",G57>10),"High Priority Review",IF(H57="Yes","Low Priority Review","No Review Needed")) -> No Review Needed | T57: =LEFT(C57,2) -> So
A58: ORD0057 | B58: Insulin Pump | C58: East | D58: Grace Kim | E58: 11 | F58: 1000 | G58: 5 | H58: Yes | I58: 45055 | J58: =E58*F58*(1-G58/100) -> 10450 | K58: =ROUND(J58*15%,2) -> 1567.5 | L58: =E58*F58 -> 11000 | M58: =DAY(I58) -> 9 | N58: =MONTH(I58) -> 5 | O58: =YEAR(I58) -> 2023 | P58: =IF(F58<500,"Low Price","High Price") -> High Price | Q58: =IF(J58>=AVERAGE(J:J),"Good","Bad") -> Bad | R58: =IF(G58>10,"High Discount",IF(G58=0,"No Discount","Low Discont")) -> Low Discont | S58: =IF(AND(H58="Yes",G58>10),"High Priority Review",IF(H58="Yes","Low Priority Review","No Review Needed")) -> Low Priority Review | T58: =LEFT(C58,2) -> Ea
A59: ORD0058 | B59: Insulin Pump | C59: North | D59: Catherine Lee | E59: 39 | F59: 1000 | G59: 0 | H59: Yes | I59: 45086 | J59: =E59*F59*(1-G59/100) -> 39000 | K59: =ROUND(J59*15%,2) -> 5850 | L59: =E59*F59 -> 39000 | M59: =DAY(I59) -> 9 | N59: =MONTH(I59) -> 6 | O59: =YEAR(I59) -> 2023 | P59: =IF(F59<500,"Low Price","High Price") -> High Price | Q59: =IF(J59>=AVERAGE(J:J),"Good","Bad") -> Good | R59: =IF(G59>10,"High Discount",IF(G59=0,"No Discount","Low Discont")) -> No Discount | S59: =IF(AND(H59="Yes",G59>10),"High Priority Review",IF(H59="Yes","Low Priority Review","No Review Needed")) -> Low Priority Review | T59: =LEFT(C59,2) -> No
A60: ORD0059 | B60: Insulin Pump | C60: East | D60: Grace Kim | E60: 27 | F60: 1000 | G60: 0 | H60: Yes | I60: 45147 | J60: =E60*F60*(1-G60/100) -> 27000 | K60: =ROUND(J60*15%,2) -> 4050 | L60: =E60*F60 -> 27000 | M60: =DAY(I60) -> 9 | N60: =MONTH(I60) -> 8 | O60: =YEAR(I60) -> 2023 | P60: =IF(F60<500,"Low Price","High Price") -> High Price | Q60: =IF(J60>=AVERAGE(J:J),"Good","Bad") -> Good | R60: =IF(G60>10,"High Discount",IF(G60=0,"No Discount","Low Discont")) -> No Discount | S60: =IF(AND(H60="Yes",G60>10),"High Priority Review",IF(H60="Yes","Low Priority Review","No Review Needed")) -> Low Priority Review | T60: =LEFT(C60,2) -> Ea
A61: ORD0060 | B61: Blood Test Kit | C61: North | D61: Eva Brown | E61: 5 | F61: 1750 | G61: 20 | H61: No | I61: 45208 | J61: =E61*F61*(1-G61/100) -> 7000 | K61: =ROUND(J61*15%,2) -> 1050 | L61: =E61*F61 -> 8750 | M61: =DAY(I61) -> 9 | N61: =MONTH(I61) -> 10 | O61: =YEAR(I61) -> 2023 | P61: =IF(F61<500,"Low Price","High Price") -> High Price | Q61: =IF(J61>=AVERAGE(J:J),"Good","Bad") -> Bad | R61: =IF(G61>10,"High Discount",IF(G61=0,"No Discount","Low Discont")) -> High Discount | S61: =IF(AND(H61="Yes",G61>10),"High Priority Review",IF(H61="Yes","Low Priority Review","No Review Needed")) -> No Review Needed | T61: =LEFT(C61,2) -> No
...

Sheet Assessment Guidelines
A1: Sr No
B2: There are 3 types of questions which can be identified by the color coding
A3: C'0' | B3: Type 1 : Column Creation - These types of questions require you to create columns based on certain conditions - You need to create the additional columns in the 'Healthcare_Sales_Dataset' subsheet (For Now, column headers are provided so simply add the formulas) - Change the dropdown in 'Solution' column to 'Completed'
A4: 1'X' | B4: Type 2 : Calculation Based - These types of questions require you to do a calculation to find out a single value based on the question - You need to add the formula in the 'Solution' column against the question - Hints for which function(s) to use are provided for the calculation based questions
A5: M'0' | B5: Type 3 : Column Modification - These types of questions require you to modify existing columns based on certain conditions - You need to perform the expected modifications as per stated on the columns in the 'Healthcare_Sales_Dataset' subsheet - Hints for the modification will be provided - Change the dropdown in 'Solution' column to 'Completed'
B6: Save the file after completing all the questions in the 'Solution' Subsheet and upload as Solution file for the respective Module

Sheet Solution
A1: Sr No | B1: Question | C1: Solution | D1: Hint
A2: C1 | B2: Create Column TotalSales with this formula - TotalSales = UnitsSold × UnitPrice × (1 – Discount%) | C2: Completed
A3: 1A | B3: Calculate the Total Sales for all orders. | C3: =SUM(Healthcare_Sales_Dataset!J2:J201) -> 3918537.5 | D3: Use SUM( ) and then range referencing.
A4: 1B | B4: Total Number of orders | C4: =COUNTA(Healthcare_Sales_Dataset!A2:A201) -> 200 | D4: Use COUNTA( ) and then range referencing.
A5: 1C | B5: Find MIN of Total Sales | C5: =MIN(Healthcare_Sales_Dataset!J2:J201) -> 1350 | D5: Use MIN( ) and then range referencing.
A6: 1D | B6: Find MAX of Total Sales | C6: =MAX(Healthcare_Sales_Dataset!J2:J201) -> 90000 | D6: Use MAX( ) and then range referencing.
A7: 1E | B7: Find AVERAGE of Total Sales | C7: =AVERAGE(Healthcare_Sales_Dataset!J2:J201) -> 19592.688 | D7: Use AVERAGE( ) and then range referencing.
A8: C3 | B8: Create Column ExpectedSales (without discounts) with this formula - ExpectedSales = UnitsSold × UnitPrice | C8: Completed
A9: C2 | B9: Create a new column Deductions with this formula - Deductions = Tax + Commission (assume 10% Tax + 5% Commission) - Round deductions to 2 decimals using ROUND( ) | C9: Completed
A10: 1F | B10: Calculate the Total ExpectedSales | C10: =SUM(Healthcare_Sales_Dataset!L2:L201) -> 4387250 | D10: Use SUM( ) and then range referencing.
A11: 1G | B11: Calculate the Total Deductions | C11: =SUM(Healthcare_Sales_Dataset!K2:K201) -> 587780.72 | D11: Use SUM( ) and then range referencing.
A12: C4 | B12: Extract Day, Month, Year from OrderDate. | C12: Completed | D12: Create 3 separate columns for each
A13: C5 | B13: If unit price < 500 → tag as “Low Price”, else “High Price”. | C13: Completed | D13: Create column PriceTag with row wise computation using IF( ) function
A14: C6 | B14: Check if a sale ≥ average → mark as “Good”, else “Ok”. | C14: Completed | D14: Create column SalesTag with row wise computation using IF( ) function combined with AVERAGE( ) function
A15: C7 | B15: If discount > 10% → tag as “High Discount”, else if discount = 0%, tag as "No Discount", else “Low discount” | C15: Completed | D15: Create Column DiscountTag with row wise computation using nested IF( ) function
A16: C8 | B16: Flag orders for Review if ReturnStatus = “Yes” AND Discount > 10%. - If both conditions are met, mark the order as "High Priority Review" - If only the return status is "Yes," mark it as "Low Priority Review" - If neither condition is met, mark it as "No Review Needed" | C16: Completed | D16: Create Column ReturnTag with nested IF( ) function combined with AND( ) function
A17: C9 | B17: Generate region codes from the first 2 characters of Region. | C17: Completed | D17: Create column RegionCode with row wise computation using LEFT( ) function
